<!-- Copyright 2021 DeepMind Technologies Limited

     Licensed under the Apache License, Version 2.0 (the "License");
     you may not use this file except in compliance with the License.
     You may obtain a copy of the License at

         http://www.apache.org/licenses/LICENSE-2.0

     Unless required by applicable law or agreed to in writing, software
     distributed under the License is distributed on an "AS IS" BASIS,
     WITHOUT WARRANTIES OR CONDITIONS OF ANY KIND, either express or implied.
     See the License for the specific language governing permissions and
     limitations under the License.
-->

<mujoco model="Particle">
  <include file="scene.xml"/>

  <option solver="CG" tolerance="1e-6" timestep=".01"/>

  <size memory="10M"/>

  <visual>
    <map stiffness="100"/>
  </visual>

  <default>
    <default class="wall">
      <geom type="plane" size=".5 .5 .05"/>
    </default>
  </default>

  <worldbody>
    <geom name="+x" class="wall" zaxis="1 0 0"  pos="-.5 0 -.25"/>
    <geom name="-x" class="wall" zaxis="-1 0 0" pos=".5 0 -.25"/>
    <geom name="+y" class="wall" zaxis="0 1 0"  pos="0 -.5 -.25"/>
    <geom name="-y" class="wall" zaxis="0 -1 0" pos="0 .5 -.25"/>
    <replicate count="15" offset=".06 0 0">
      <replicate count="15" offset="0 .06 0">
        <body pos="-.42 -.42 .1">
          <joint type="slide" axis="1 0 0"/>
          <joint type="slide" axis="0 1 0"/>
          <joint type="hinge" axis="0 0 1"/>
          <geom type="ellipsoid" size=".025 .02 .015" rgba=".8 .2 .1 1"/>
        </body>
      </replicate>
    </replicate>
  </worldbody>
</mujoco>
